<?xml version="1.0" ?>
<robot name="stompy_leg">
  <joint name="stompy_leg__hip_to_thigh" type="revolute">
    <parent link="stompy_leg__hip"/>
    <child link="stompy_leg__thigh"/>
    <origin rpy="0  0  0" xyz="0.279  0     0"/>
    <axis xyz="0  1  0"/>
    <limit effort="0.0" lower="0.0" upper="0.6981" velocity="0.0"/>
  </joint>
  <joint name="stompy_leg__thigh_to_calf_upper" type="revolute">
    <parent link="stompy_leg__thigh"/>
    <child link="stompy_leg__calf_upper"/>
    <origin rpy="0  0  0" xyz="0.14399  0       1.364"/>
    <axis xyz="0  1  0"/>
    <limit effort="0.0" lower="-0.6981" upper="0.0" velocity="0.0"/>
  </joint>
  <joint name="stompy_leg__calf_upper_to_linkage_upper" type="fixed">
    <parent link="stompy_leg__calf_upper"/>
    <child link="stompy_leg__linkage_upper"/>
    <origin rpy="0  0  0" xyz="0.0016  0     -0.8185"/>
    <axis xyz="0  1  0"/>
    <limit effort="0" lower="0" upper="0" velocity="0"/>
  </joint>
  <joint name="stompy_leg__calf_upper_to_linkage_lower" type="fixed">
    <parent link="stompy_leg__calf_upper"/>
    <child link="stompy_leg__linkage_lower"/>
    <origin rpy="0  0  0" xyz="0.0388  0     -1.121"/>
    <axis xyz="0  1  0"/>
    <limit effort="0" lower="0" upper="0" velocity="0"/>
  </joint>
  <joint name="stompy_leg__linkage_upper_to_calf_lower" type="revolute">
    <parent link="stompy_leg__linkage_upper"/>
    <child link="stompy_leg__calf_lower"/>
    <origin rpy="0  0  0" xyz="0.203  0     0"/>
    <axis xyz="0  1  0"/>
    <limit effort="0.0" lower="0.0" upper="0.349" velocity="0.0"/>
  </joint>
  <joint name="stompy_leg__linkage_lower_to_calf_lower" type="fixed">
    <parent link="stompy_leg__linkage_lower"/>
    <child link="stompy_leg__calf_lower"/>
    <origin rpy="0  0  0" xyz="2.02900000e-01   0.00000000e+00   1.00000000e-04"/>
    <axis xyz="0  1  0"/>
    <limit effort="0" lower="0" upper="0" velocity="0"/>
  </joint>
  <joint name="stompy_leg__calf_lower_to_ankle" type="revolute">
    <parent link="stompy_leg__calf_lower"/>
    <child link="stompy_leg__ankle"/>
    <origin rpy="0  0  0" xyz="-0.0171  0     -0.6656"/>
    <axis xyz="0  1  0"/>
    <limit effort="0.0" lower="-1.3962" upper="1.3962" velocity="0.0"/>
  </joint>
  <joint name="stompy_leg__ankle_to_foot" type="revolute">
    <parent link="stompy_leg__ankle"/>
    <child link="stompy_leg__foot"/>
    <origin rpy="0  0  0" xyz="0      0     -0.0412"/>
    <axis xyz="1  0  0"/>
    <limit effort="0.0" lower="-1.3962" upper="1.3962" velocity="0.0"/>
  </joint>
  <link name="stompy_leg__hip">
    <inertial>
      <mass value="28.231"/>
      <origin rpy="0  0  0" xyz="0.11386  0       0.03317"/>
      <inertia ixx="0.417" ixy="0." ixz="0.026" iyy="0.327" iyz="0." izz="0.337"/>
    </inertial>
    <collision name="stompy_leg__collision">
      <origin rpy="0  0  0" xyz="0.1106   0       0.04218"/>
      <geometry>
        <box size="0.388937 0.411136 0.304614"/>
      </geometry>
    </collision>
    <visual name="stompy_leg__visual">
      <origin rpy="0  0  0" xyz="0  0  0"/>
      <geometry>
        <mesh filename="package:///home/brett/Repositories/braingram/stompy_simulation/gazebo/models/stompy_leg/meshes/hip.stl" scale="1.0 1.0 1.0"/>
      </geometry>
    </visual>
  </link>
  <link name="stompy_leg__thigh">
    <inertial>
      <mass value="64.053"/>
      <origin rpy="0  0  0" xyz="-0.04116  0       0.52666"/>
      <inertia ixx="10.62" ixy="0." ixz="-0.34" iyy="10.92" iyz="0." izz="1.334"/>
    </inertial>
    <collision name="stompy_leg__collision">
      <origin rpy="0  0  0" xyz="-0.04764  0       0.70869"/>
      <geometry>
        <box size="0.525414 0.273050 1.446567"/>
      </geometry>
    </collision>
    <visual name="stompy_leg__visual">
      <origin rpy="0  0  0" xyz="0  0  0"/>
      <geometry>
        <mesh filename="package:///home/brett/Repositories/braingram/stompy_simulation/gazebo/models/stompy_leg/meshes/thigh.stl" scale="1.0 1.0 1.0"/>
      </geometry>
    </visual>
  </link>
  <link name="stompy_leg__calf_upper">
    <inertial>
      <mass value="39.145"/>
      <origin rpy="0  0  0" xyz="0.03528  0      -0.33951"/>
      <inertia ixx="5.471" ixy="0." ixz="1.148" iyy="5.636" iyz="0." izz="0.775"/>
    </inertial>
    <collision name="stompy_leg__collision">
      <origin rpy="0  0  0" xyz="3.28400000e-02  -1.00000000e-05  -3.32310000e-01"/>
      <geometry>
        <box size="0.397840 0.346075 1.385496"/>
      </geometry>
    </collision>
    <visual name="stompy_leg__visual">
      <origin rpy="0  0  0" xyz="0  0  0"/>
      <geometry>
        <mesh filename="package:///home/brett/Repositories/braingram/stompy_simulation/gazebo/models/stompy_leg/meshes/calf_upper.stl" scale="1.0 1.0 1.0"/>
      </geometry>
    </visual>
  </link>
  <link name="stompy_leg__linkage_upper">
    <inertial>
      <mass value="3.754"/>
      <origin rpy="0  0  0" xyz="1.02910000e-01   0.00000000e+00   1.00000000e-05"/>
      <inertia ixx="0.028" ixy="0." ixz="0." iyy="0.022" iyz="0" izz="0.009"/>
    </inertial>
    <collision name="stompy_leg__collision">
      <origin rpy="0  0  0" xyz="1.01380000e-01   0.00000000e+00  -1.00000000e-05"/>
      <geometry>
        <box size="0.273050 0.146050 0.082518"/>
      </geometry>
    </collision>
    <visual name="stompy_leg__visual">
      <origin rpy="0  0  0" xyz="0  0  0"/>
      <geometry>
        <mesh filename="package:///home/brett/Repositories/braingram/stompy_simulation/gazebo/models/stompy_leg/meshes/calf_link.stl" scale="1.0 1.0 1.0"/>
      </geometry>
    </visual>
  </link>
  <link name="stompy_leg__linkage_lower">
    <inertial>
      <mass value="3.754"/>
      <origin rpy="0  0  0" xyz="1.02910000e-01   0.00000000e+00   1.00000000e-05"/>
      <inertia ixx="0.028" ixy="0." ixz="0." iyy="0.022" iyz="0" izz="0.009"/>
    </inertial>
    <collision name="stompy_leg__collision">
      <origin rpy="0  0  0" xyz="1.01380000e-01   0.00000000e+00  -1.00000000e-05"/>
      <geometry>
        <box size="0.273050 0.146050 0.082518"/>
      </geometry>
    </collision>
    <visual name="stompy_leg__visual">
      <origin rpy="0  0  0" xyz="0  0  0"/>
      <geometry>
        <mesh filename="package:///home/brett/Repositories/braingram/stompy_simulation/gazebo/models/stompy_leg/meshes/calf_link.stl" scale="1.0 1.0 1.0"/>
      </geometry>
    </visual>
  </link>
  <link name="stompy_leg__calf_lower">
    <inertial>
      <mass value="18.983"/>
      <origin rpy="0  0  0" xyz="0.01114  0      -0.10264"/>
      <inertia ixx="1.827" ixy="0." ixz="0.243" iyy="1.859" iyz="0." izz="0.145"/>
    </inertial>
    <collision name="stompy_leg__collision">
      <origin rpy="0  0  0" xyz="0.01567  0      -0.10663"/>
      <geometry>
        <box size="0.237352 0.180975 1.122347"/>
      </geometry>
    </collision>
    <visual name="stompy_leg__visual">
      <origin rpy="0  0  0" xyz="-0.0371  0      0.3024"/>
      <geometry>
        <mesh filename="package:///home/brett/Repositories/braingram/stompy_simulation/gazebo/models/stompy_leg/meshes/calf_lower.stl" scale="1.0 1.0 1.0"/>
      </geometry>
    </visual>
  </link>
  <link name="stompy_leg__ankle">
    <inertial>
      <mass value="1.391"/>
      <origin rpy="0  0  0" xyz="0       0      -0.01638"/>
      <inertia ixx="0.002" ixy="0" ixz="0" iyy="0.001" iyz="0" izz="0.002"/>
    </inertial>
    <collision name="stompy_leg__collision">
      <origin rpy="0  0  0" xyz="0       0      -0.01709"/>
      <geometry>
        <box size="0.073025 0.127000 0.100314"/>
      </geometry>
    </collision>
    <visual name="stompy_leg__visual">
      <origin rpy="0  0  0" xyz="0  0  0"/>
      <geometry>
        <mesh filename="package:///home/brett/Repositories/braingram/stompy_simulation/gazebo/models/stompy_leg/meshes/ankle.stl" scale="1.0 1.0 1.0"/>
      </geometry>
    </visual>
  </link>
  <link name="stompy_leg__foot">
    <inertial>
      <mass value="9.307"/>
      <origin rpy="0  0  0" xyz="0       0      -0.11187"/>
      <inertia ixx="0.069" ixy="0" ixz="0" iyy="0.069" iyz="0" izz="0.102"/>
    </inertial>
    <collision name="stompy_leg__collision">
      <origin rpy="0  0  0" xyz="0       0      -0.11187"/>
      <geometry>
        <box size="0.355474 0.355348 0.188913"/>
      </geometry>
    </collision>
    <visual name="stompy_leg__visual">
      <origin rpy="0  0  0" xyz="0  0  0"/>
      <geometry>
        <mesh filename="package:///home/brett/Repositories/braingram/stompy_simulation/gazebo/models/stompy_leg/meshes/foot.stl" scale="1.0 1.0 1.0"/>
      </geometry>
    </visual>
  </link>
</robot>
